<mujoco model="Delta">
  <!-- <option>
      <flag contact="disable"/>
  </option> -->
  <compiler angle="radian" meshdir="assets"/>
  <option timestep="0.0001" gravity="0 0 -9.81" integrator="implicit" iterations="100" density="1" viscosity="1e-5"/>

  <default>
    <joint type="hinge" frictionloss="0.0001" damping='0.00005' limited="true" range="-3.14 3.14"/>
    <position ctrllimited="false" forcelimited="false"  kp="100" kv="10"/>
  </default>

  <asset>
    <mesh name="base_link" file="base_link.STL"/>
    <mesh name="motor_arm_link1" file="motor_arm_link1.STL"/>
    <mesh name="right_elbow_link1" file="right_elbow_link1.STL"/>
    <mesh name="right_arm_link1" file="right_arm_link1.STL"/>
    <mesh name="right_hinge_link1" file="right_hinge_link1.STL"/>
    <mesh name="right_end_link1" file="right_end_link1.STL"/>
    <mesh name="left_elbow_link1" file="left_elbow_link1.STL"/>
    <mesh name="left_arm_link1" file="left_arm_link1.STL"/>
    <mesh name="left_hinge_link1" file="left_hinge_link1.STL"/>
    <mesh name="left_end_link1" file="left_end_link1.STL"/>
    <mesh name="end_platform" file="end_platform.STL"/>
    <mesh name="motor_arm_link2" file="motor_arm_link2.STL"/>
    <mesh name="right_elbow_link2" file="right_elbow_link2.STL"/>
    <mesh name="right_arm_link2" file="right_arm_link2.STL"/>
    <mesh name="right_hinge_link2" file="right_hinge_link2.STL"/>
    <mesh name="right_end_link2" file="right_end_link2.STL"/>
    <mesh name="left_elbow_link2" file="left_elbow_link2.STL"/>
    <mesh name="left_arm_link2" file="left_arm_link2.STL"/>
    <mesh name="left_hinge_link2" file="left_hinge_link2.STL"/>
    <mesh name="left_end_link2" file="left_end_link2.STL"/>
    <mesh name="motor_arm_link3" file="motor_arm_link3.STL"/>
    <mesh name="right_elbow_link3" file="right_elbow_link3.STL"/>
    <mesh name="right_arm_link3" file="right_arm_link3.STL"/>
    <mesh name="right_hinge_link3" file="right_hinge_link3.STL"/>
    <mesh name="right_end_link3" file="right_end_link3.STL"/>
    <mesh name="left_elbow_link3" file="left_elbow_link3.STL"/>
    <mesh name="left_arm_link3" file="left_arm_link3.STL"/>
    <mesh name="left_hinge_link3" file="left_hinge_link3.STL"/>
    <mesh name="left_end_link3" file="left_end_link3.STL"/>
    <texture name="grid" type="2d" builtin="checker" rgb1=".1 .2 .3" rgb2=".2 .3 .4" width="100" height="100"/>
    <material name="grid" texture="grid" texrepeat="5 5" reflectance="0.0"/>
  </asset>

  <worldbody>
    <!-- This is the floor. -->
    <geom pos="0 0 0" size="0 0 0.05" type="plane" material="grid"/>
    
    <light pos="0 0 10."/>


    <body name="UAV_Delta_platform" pos="0 0 0.13271" quat = "1. 0. 0. 0">
      <freejoint />
      <body name="UAV_body" pos="0 0 0.04" quat = "1. 0. 0. 0">
        <site name="imu"/>
        <site name="UAV_center" pos=" 0 0 0"  size="0.01"  quat = "1.0 0.0 0.0 0." rgba="0.8 0.8 0.3 1"/>
        <geom name="core" type="box" pos="0 0 0" quat = "1. 0. 0. 0" size="0.06 0.035 0.025"  rgba="0.3 0.3 0.3 0.3" mass = ".2"/>
        <geom name="a00" type="box" pos=".071 0.071 0" size="0.15 0.01 0.0025"  quat = ".924 0.0 0.0 0.383" rgba="0.3 0.3 0.8 1" mass = ".025"/>
        <geom name="a10" type="box" pos=".071 -0.071 0" size="0.15 0.01 0.0025"  quat = ".383 0.0 0.0 0.924" rgba="0.3 0.3 0.8 1" mass = ".025"/>
        <geom name="a20" type="box" pos="-0.071 -0.071 0" size="0.15 0.01 0.0025"  quat = "-.383 0.0 0.0 0.924" rgba="0.3 0.3 0.8 1" mass = ".025"/>
        <geom name="a30" type="box" pos="-.071 0.071 0" size="0.15 0.01 0.0025"  quat = ".924 0.0 0.0 -0.383" rgba="0.3 0.3 0.8 1" mass = ".025"/>

        <site name="motor1" type="cylinder" pos=" 0.18  0.18 0.01"  size="0.01 0.0025"  quat = "1.0 0.0 0.0 0." rgba="0.3 0.8 0.3 1"/>
        <site name="motor2" type="cylinder" pos=" 0.18 -0.18 0.01"  size="0.01 0.0025"  quat = "1.0 0.0 0.0 0." rgba="0.3 0.8 0.3 1"/>
        <site name="motor3" type="cylinder" pos="-0.18 -0.18 0.01"  size="0.01 0.0025"  quat = "1.0 0.0 0.0 0." rgba="0.3 0.8 0.3 1"/>
        <site name="motor4" type="cylinder" pos="-0.18  0.18 0.01"  size="0.01 0.0025"  quat = "1.0 0.0 0.0 0." rgba="0.3 0.8 0.3 1"/>

        <!-- Thruster geometries for collisions since site's are excluded from collision checking -->
        <geom name="prop1" type="cylinder" pos=" 0.18  0.18  0.01" size="0.1 0.0025"  quat = "1.0 0.0 0.0 0." rgba="1 0 0 1" mass = ".025"/>
        <geom name="prop2" type="cylinder" pos=" 0.18  -0.18  0.01" size="0.1 0.0025"  quat = "1.0 0.0 0.0 0." rgba="0 0.3 1 1" mass = ".025"/>
        <geom name="prop3" type="cylinder" pos=" -0.18  -0.18  0.01" size="0.1 0.0025"  quat = "1.0 0.0 0.0 0." rgba="1 0 0.8 1" mass = ".025"/>
        <geom name="prop4" type="cylinder" pos=" -0.18  0.18  0.01" size="0.1 0.0025"  quat = "1.0 0.0 0.0 0." rgba="0.3 0.8 0.3 1" mass = ".025"/>
      </body>
      <camera name="track" pos="0 -1. .3" xyaxes="1 0 0 0 1 2" mode="track"/>
      <body name="Delta_base_body">
        <site name="Delta_base_center" pos=" 0 0 0"  size="0.01"  quat = "1.0 0.0 0.0 0." rgba="0.8 0.8 0.3 1"/>
        <geom type="mesh" contype="0" conaffinity="0" group="1" density="1" rgba="0.57255 1 0.27059 1" mesh="base_link"/>
        <geom type="mesh" rgba="0.57255 1 0.27059 1" mesh="base_link"/>
      </body>  
      <!-- <geom pos="0 0 -0.13271" quat="1 0 0 0" type="mesh" contype="0" conaffinity="0" group="1" density="1" rgba="0.79216 0.81961 0.93333 1" mesh="end_platform"/>
      <geom pos="0 0 -0.13271" quat="1 0 0 0" type="mesh" rgba="0.79216 0.81961 0.93333 1" mesh="end_platform"/> -->
      <body name="motor_arm_link1" pos="0.074577 0 0">
        <inertial pos="0.048659 4.3413e-11 -3.3963e-09" quat="0.5 0.5 -0.5 0.5" mass="0.0086736" diaginertia="1.9546e-06 1.2676e-06 1.1572e-06"/>
        <joint name="motor_arm_joint1" pos="0 0 0" axis="0 -1 0" damping='10'/>
        <geom type="mesh" contype="0" conaffinity="0" group="1" density="1" rgba="1 0.50196 0.50196 1" mesh="motor_arm_link1"/>
        <geom type="mesh" rgba="1 0.50196 0.50196 1" mesh="motor_arm_link1"/>
        <body name="right_elbow_link1" pos="0.1 0.026 0" quat="0.644891 0.290023 0.290025 0.644893">
          <inertial pos="-0.00098819 3.0494e-10 -4.6362e-09" quat="0.5 0.5 0.5 0.5" mass="0.00085837" diaginertia="2.0402e-08 1.8973e-08 1.153e-08"/>
          <joint name="right_elbow_joint1" pos="0 0 0" axis="-1 0 0"  />
          <geom type="mesh" contype="0" conaffinity="0" group="1" density="1" rgba="0.79216 0.81961 0.93333 1" mesh="right_elbow_link1"/>
          <geom type="mesh" rgba="0.79216 0.81961 0.93333 1" mesh="right_elbow_link1"/>
          <body name="right_arm_link1">
            <inertial pos="-8.6914e-09 0 -0.1" quat="0.707107 0 0 0.707107" mass="0.0075206" diaginertia="4.0858e-06 4.085e-06 2.4932e-09"/>
            <joint name="right_arm_joint1" pos="0 0 0" axis="0 -1 0"  />
            <geom type="mesh" contype="0" conaffinity="0" group="1" density="1" rgba="1 1 0 1" mesh="right_arm_link1"/>
            <geom type="mesh" rgba="1 1 0 1" mesh="right_arm_link1"/>
            <body name="right_hinge_link1" pos="0 0 -0.2">
              <inertial pos="-0.00098819 -3.0494e-10 4.6362e-09" quat="0.5 0.5 0.5 0.5" mass="0.00085837" diaginertia="2.0402e-08 1.8973e-08 1.153e-08"/>
              <joint name="right_hinge_joint1" pos="0 0 0" axis="0 1 0"  />
              <geom type="mesh" contype="0" conaffinity="0" group="1" density="1" rgba="0.79216 0.81961 0.93333 1" mesh="right_hinge_link1"/>
              <geom type="mesh" rgba="0.79216 0.81961 0.93333 1" mesh="right_hinge_link1"/>
              <body name="right_end_link1">
                <inertial pos="-0.013549 4.0775e-05 -4.5973e-05" quat="0.306307 0.63732 0.273553 0.65205" mass="0.0012596" diaginertia="3.85901e-08 2.95879e-08 2.3009e-08"/>
                <joint name="right_end_joint1" pos="0 0 0" axis="-1 0 0"  />
                <geom type="mesh" contype="0" conaffinity="0" group="1" density="1" rgba="0.50196 0.50196 1 1" mesh="right_end_link1"/>
                <geom type="mesh" rgba="0.50196 0.50196 1 1" mesh="right_end_link1"/>
              </body>
            </body>
          </body>
        </body>
        <body name="left_elbow_link1" pos="0.1 -0.026 0" quat="0.644891 0.290023 0.290025 0.644893">
          <inertial pos="0.00098819 3.0494e-10 4.6362e-09" quat="0.5 0.5 0.5 0.5" mass="0.00085837" diaginertia="2.0402e-08 1.8973e-08 1.153e-08"/>
          <joint name="left_elbow_joint1" pos="0 0 0" axis="1 0 0"/>
          <geom type="mesh" contype="0" conaffinity="0" group="1" density="1" rgba="0.79216 0.81961 0.93333 1" mesh="left_elbow_link1"/>
          <geom type="mesh" rgba="0.79216 0.81961 0.93333 1" mesh="left_elbow_link1"/>
          <body name="left_arm_link1">
            <inertial pos="-8.6914e-09 0 -0.1" quat="0.707107 0 0 0.707107" mass="0.0075206" diaginertia="4.0858e-06 4.085e-06 2.4932e-09"/>
            <joint name="left_arm_joint1" pos="0 0 0" axis="0 -1 0"/>
            <geom type="mesh" contype="0" conaffinity="0" group="1" density="1" rgba="1 1 0 1" mesh="left_arm_link1"/>
            <geom type="mesh" rgba="1 1 0 1" mesh="left_arm_link1"/>
            <body name="left_hinge_link1" pos="0 0 -0.2">
              <inertial pos="0.00098819 3.0494e-10 4.6362e-09" quat="0.5 0.5 0.5 0.5" mass="0.00085837" diaginertia="2.0402e-08 1.8973e-08 1.153e-08"/>
              <joint name="left_hinge_joint1" pos="0 0 0" axis="0 -1 0"/>
              <geom type="mesh" contype="0" conaffinity="0" group="1" density="1" rgba="0.79216 0.81961 0.93333 1" mesh="left_hinge_link1"/>
              <geom type="mesh" rgba="0.79216 0.81961 0.93333 1" mesh="left_hinge_link1"/>
              <body name="left_end_link1">
                <inertial pos="0.013549 4.0775e-05 -4.5973e-05" quat="0.273553 0.65205 0.306307 0.63732" mass="0.0012596" diaginertia="3.85901e-08 2.95879e-08 2.3009e-08"/>
                <joint name="left_end_joint1" pos="0 0 0" axis="1 0 0"/>
                <geom type="mesh" contype="0" conaffinity="0" group="1" density="1" rgba="0 1 1 1" mesh="left_end_link1"/>
                <geom type="mesh" rgba="0 1 1 1" mesh="left_end_link1"/>
              </body>
            </body>
          </body>
        </body>
      </body>
      <body name="motor_arm_link2" pos="-0.037289 0.064586 0" quat="0.499998 0 0 0.866027">
        <inertial pos="0.048659 -1.1526e-10 -3.1381e-09" quat="0.5 0.5 -0.5 0.5" mass="0.0086736" diaginertia="1.9546e-06 1.2676e-06 1.1572e-06"/>
        <joint name="motor_arm_joint2" pos="0 0 0" axis="0 -1 0" damping='10'/>
        <geom type="mesh" contype="0" conaffinity="0" group="1" density="1" rgba="1 0.50196 0.50196 1" mesh="motor_arm_link2"/>
        <geom type="mesh" rgba="1 0.50196 0.50196 1" mesh="motor_arm_link2"/>
        <body name="right_elbow_link2" pos="0.1 0.026 0" quat="0.644891 0.290023 0.290025 0.644893">
          <inertial pos="-0.00098819 1.6333e-09 -2.2058e-09" quat="0.5 0.5 0.5 0.5" mass="0.00085837" diaginertia="2.0402e-08 1.8973e-08 1.153e-08"/>
          <joint name="right_elbow_joint2" pos="0 0 0" axis="-1 0 0"/>
          <geom type="mesh" contype="0" conaffinity="0" group="1" density="1" rgba="0.79216 0.81961 0.93333 1" mesh="right_elbow_link2"/>
          <geom type="mesh" rgba="0.79216 0.81961 0.93333 1" mesh="right_elbow_link2"/>
          <body name="right_arm_link2">
            <inertial pos="-8.6914e-09 0 -0.1" quat="0.707107 0 0 0.707107" mass="0.0075206" diaginertia="4.0858e-06 4.085e-06 2.4932e-09"/>
            <joint name="right_arm_joint2" pos="0 0 0" axis="0 -1 0"/>
            <geom type="mesh" contype="0" conaffinity="0" group="1" density="1" rgba="1 1 0 1" mesh="right_arm_link2"/>
            <geom type="mesh" rgba="1 1 0 1" mesh="right_arm_link2"/>
            <body name="right_hinge_link2" pos="0 0 -0.2">
              <inertial pos="-0.00098819 9.8853e-10 7.0548e-09" quat="0.5 0.5 0.5 0.5" mass="0.00085837" diaginertia="2.0402e-08 1.8973e-08 1.153e-08"/>
              <joint name="right_hinge_joint2" pos="0 0 0" axis="0 1 0"/>
              <geom type="mesh" contype="0" conaffinity="0" group="1" density="1" rgba="0.79216 0.81961 0.93333 1" mesh="right_hinge_link2"/>
              <geom type="mesh" rgba="0.79216 0.81961 0.93333 1" mesh="right_hinge_link2"/>
              <body name="right_end_link2">
                <inertial pos="-0.013549 4.0775e-05 -4.5973e-05" quat="0.306307 0.63732 0.273553 0.65205" mass="0.0012596" diaginertia="3.85901e-08 2.95879e-08 2.3009e-08"/>
                <joint name="right_end_joint2" pos="0 0 0" axis="-1 0 0"/>
                <geom type="mesh" contype="0" conaffinity="0" group="1" density="1" rgba="0.50196 0.50196 1 1" mesh="right_end_link2"/>
                <geom type="mesh" rgba="0.50196 0.50196 1 1" mesh="right_end_link2"/>
              </body>
            </body>
          </body>
        </body>
        <body name="left_elbow_link2" pos="0.1 -0.026 0" quat="0.644891 0.290023 0.290025 0.644893">
          <inertial pos="0.00098819 -9.7302e-10 2.2002e-09" quat="0.5 0.5 0.5 0.5" mass="0.00085837" diaginertia="2.0402e-08 1.8973e-08 1.153e-08"/>
          <joint name="left_elbow_joint2" pos="0 0 0" axis="1 0 0"/>
          <geom type="mesh" contype="0" conaffinity="0" group="1" density="1" rgba="0.79216 0.81961 0.93333 1" mesh="left_elbow_link2"/>
          <geom type="mesh" rgba="0.79216 0.81961 0.93333 1" mesh="left_elbow_link2"/>
          <body name="left_arm_link2">
            <inertial pos="-8.6914e-09 0 -0.1" quat="0.707107 0 0 0.707107" mass="0.0075206" diaginertia="4.0858e-06 4.085e-06 2.4932e-09"/>
            <joint name="left_arm_joint2" pos="0 0 0" axis="0 -1 0"/>
            <geom type="mesh" contype="0" conaffinity="0" group="1" density="1" rgba="1 1 0 1" mesh="left_arm_link2"/>
            <geom type="mesh" rgba="1 1 0 1" mesh="left_arm_link2"/>
            <body name="left_hinge_link2" pos="0 0 -0.2">
              <inertial pos="0.00098819 -9.7302e-10 2.2002e-09" quat="0.5 0.5 0.5 0.5" mass="0.00085837" diaginertia="2.0402e-08 1.8973e-08 1.153e-08"/>
              <joint name="left_hinge_joint2" pos="0 0 0" axis="0 -1 0"/>
              <geom type="mesh" contype="0" conaffinity="0" group="1" density="1" rgba="0.79216 0.81961 0.93333 1" mesh="left_hinge_link2"/>
              <geom type="mesh" rgba="0.79216 0.81961 0.93333 1" mesh="left_hinge_link2"/>
              <body name="left_end_link2">
                <inertial pos="0.013549 4.0775e-05 -4.5973e-05" quat="0.273553 0.65205 0.306307 0.63732" mass="0.0012596" diaginertia="3.85901e-08 2.95879e-08 2.3009e-08"/>
                <joint name="left_end_joint2" pos="0 0 0" axis="1 0 0"/>
                <geom type="mesh" contype="0" conaffinity="0" group="1" density="1" rgba="0 1 1 1" mesh="left_end_link2"/>
                <geom type="mesh" rgba="0 1 1 1" mesh="left_end_link2"/>
              </body>
            </body>
          </body>
        </body>
      </body>
      <body name="motor_arm_link3" pos="-0.037289 -0.064586 0" quat="0.499998 0 0 -0.866027">
        <inertial pos="0.048659 1.1069e-10 -3.4522e-09" quat="0.5 0.5 -0.5 0.5" mass="0.0086736" diaginertia="1.9546e-06 1.2676e-06 1.1572e-06"/>
        <joint name="motor_arm_joint3" pos="0 0 0" axis="0 -1 0" damping='10'/>
        <geom type="mesh" contype="0" conaffinity="0" group="1" density="1" rgba="1 0.50196 0.50196 1" mesh="motor_arm_link3"/>
        <geom type="mesh" rgba="1 0.50196 0.50196 1" mesh="motor_arm_link3"/>
        <body name="right_elbow_link3" pos="0.1 0.026 0" quat="0.644891 0.290023 0.290025 0.644893">
          <inertial pos="-0.00098819 -9.8853e-10 -7.0473e-09" quat="0.5 0.5 0.5 0.5" mass="0.00085837" diaginertia="2.0402e-08 1.8973e-08 1.153e-08"/>
          <joint name="right_elbow_joint3" pos="0 0 0" axis="-1 0 0"/>
          <geom type="mesh" contype="0" conaffinity="0" group="1" density="1" rgba="0.79216 0.81961 0.93333 1" mesh="right_elbow_link3"/>
          <geom type="mesh" rgba="0.79216 0.81961 0.93333 1" mesh="right_elbow_link3"/>
          <body name="right_arm_link3">
            <inertial pos="-8.6914e-09 0 -0.1" quat="0.707107 0 0 0.707107" mass="0.0075206" diaginertia="4.0858e-06 4.085e-06 2.4932e-09"/>
            <joint name="right_arm_joint3" pos="0 0 0" axis="0 -1 0"/>
            <geom type="mesh" contype="0" conaffinity="0" group="1" density="1" rgba="1 1 0 1" mesh="right_arm_link3"/>
            <geom type="mesh" rgba="1 1 0 1" mesh="right_arm_link3"/>
            <body name="right_hinge_link3" pos="0 0 -0.2">
              <inertial pos="-0.0009882 -1.6333e-09 2.1981e-09" quat="0.5 0.5 0.5 0.5" mass="0.00085837" diaginertia="2.0402e-08 1.8973e-08 1.153e-08"/>
              <joint name="right_hinge_joint3" pos="0 0 0" axis="0 1 0"/>
              <geom type="mesh" contype="0" conaffinity="0" group="1" density="1" rgba="0.79216 0.81961 0.93333 1" mesh="right_hinge_link3"/>
              <geom type="mesh" rgba="0.79216 0.81961 0.93333 1" mesh="right_hinge_link3"/>
              <body name="right_end_link3">
                <inertial pos="-0.013549 4.0775e-05 -4.5973e-05" quat="0.306307 0.63732 0.273553 0.65205" mass="0.0012596" diaginertia="3.85901e-08 2.95879e-08 2.3009e-08"/>
                <joint name="right_end_joint3" pos="0 0 0" axis="-1 0 0"/>
                <geom type="mesh" contype="0" conaffinity="0" group="1" density="1" rgba="0.50196 0.50196 1 1" mesh="right_end_link3"/>
                <geom type="mesh" rgba="0.50196 0.50196 1 1" mesh="right_end_link3"/>
              </body>
            </body>
          </body>
        </body>
        <body name="left_elbow_link3" pos="0.1 -0.026 0" quat="0.644891 0.290023 0.290025 0.644893">
          <inertial pos="0.00098819 1.6483e-09 7.0573e-09" quat="0.5 0.5 0.5 0.5" mass="0.00085837" diaginertia="2.0402e-08 1.8973e-08 1.153e-08"/>
          <joint name="left_elbow_joint3" pos="0 0 0" axis="1 0 0"/>
          <geom type="mesh" contype="0" conaffinity="0" group="1" density="1" rgba="0.79216 0.81961 0.93333 1" mesh="left_elbow_link3"/>
          <geom type="mesh" rgba="0.79216 0.81961 0.93333 1" mesh="left_elbow_link3"/>
          <body name="left_arm_link3">
            <inertial pos="-8.6914e-09 0 -0.1" quat="0.707107 0 0 0.707107" mass="0.0075206" diaginertia="4.0858e-06 4.085e-06 2.4932e-09"/>
            <joint name="left_arm_joint3" pos="0 0 0" axis="0 -1 0"/>
            <geom type="mesh" contype="0" conaffinity="0" group="1" density="1" rgba="1 1 0 1" mesh="left_arm_link3"/>
            <geom type="mesh" rgba="1 1 0 1" mesh="left_arm_link3"/>
            <body name="left_hinge_link3" pos="0 0 -0.2">
              <inertial pos="0.00098819 1.6483e-09 7.0573e-09" quat="0.5 0.5 0.5 0.5" mass="0.00085837" diaginertia="2.0402e-08 1.8973e-08 1.153e-08"/>
              <joint name="left_hinge_joint3" pos="0 0 0" axis="0 -1 0"/>
              <geom type="mesh" contype="0" conaffinity="0" group="1" density="1" rgba="0.79216 0.81961 0.93333 1" mesh="left_hinge_link3"/>
              <geom type="mesh" rgba="0.79216 0.81961 0.93333 1" mesh="left_hinge_link3"/>
              <body name="left_end_link3">
                <inertial pos="0.013549 4.0775e-05 -4.5973e-05" quat="0.273553 0.65205 0.306307 0.63732" mass="0.0012596" diaginertia="3.85901e-08 2.95879e-08 2.3009e-08"/>
                <joint name="left_end_joint3" pos="0 0 0" axis="1 0 0"/>
                <geom type="mesh" contype="0" conaffinity="0" group="1" density="1" rgba="0 1 1 1" mesh="left_end_link3"/>
                <geom type="mesh" rgba="0 1 1 1" mesh="left_end_link3"/>
              </body>
            </body>
          </body>
        </body>
      </body>
    </body>

    <body name="end_platform" pos="0 0 0" >
      <freejoint />
      <site name="end_platform_center" pos=" 0 0 0"  size="0.01"  quat = "1.0 0.0 0.0 0." rgba="0.8 0.8 0.3 1"/>
      <inertial pos="0 0 0" quat="1 0 0 0" mass="0.0125206" diaginertia="4.0858e-06 4.085e-06 2.4932e-09"/>
      <!-- <geom pos="0 0 -0.13271" quat="1 0 0 0" type="mesh" contype="0" conaffinity="0" group="1" density="0" rgba="0.79216 0.81961 0.93333 1" mesh="end_platform"/> -->
      <geom pos="0 0 0" quat="1 0 0 0" type="mesh" rgba="0.79216 0.81961 0.93333 1" mesh="end_platform"/>
    </body>

  </worldbody>

  <contact>
      <exclude name="e0" body1="right_end_link1" body2="end_platform" />
      <exclude name="e1" body1="left_end_link1" body2="end_platform" />
      <exclude name="e2" body1="right_end_link2" body2="end_platform" />
      <exclude name="e3" body1="left_end_link2" body2="end_platform" />
      <exclude name="e4" body1="right_end_link3" body2="end_platform" />
      <exclude name="e5" body1="left_end_link3" body2="end_platform" />            
      <!-- <exclude name="e1" body1="b0" body2="b2" /> -->
      <!-- <exclude name="e2" body1="b3" body2="b4" />
      <exclude name="e3" body1="b3" body2="b5" />
      <exclude name="e4" body1="b1" body2="b4" />
      <exclude name="e5" body1="b2" body2="b5" /> -->
  </contact>

  <equality>
    <weld name="c1" body1="right_end_link1" body2="end_platform" solref="0.0001 0.99" solimp="0.99 0.999 0.0001" torquescale="1" />
    <weld name="c2" body1="left_end_link1" body2="end_platform" solref="0.0001 0.99" solimp="0.99 0.999 0.0001" torquescale="1" />
    <weld name="c3" body1="right_end_link2" body2="end_platform" solref="0.0001 0.99" solimp="0.99 0.999 0.0001" torquescale="1" />
    <weld name="c4" body1="left_end_link2" body2="end_platform" solref="0.0001 0.99" solimp="0.99 0.999 0.0001" torquescale="1" />
    <weld name="c5" body1="right_end_link3" body2="end_platform" solref="0.0001 0.99" solimp="0.99 0.999 0.0001" torquescale="1" />
    <weld name="c6" body1="left_end_link3" body2="end_platform" solref="0.0001 0.99" solimp="0.99 0.999 0.0001" torquescale="1" />


      <!-- <connect name="c1" body1="right_end_link1" body2="end_platform" anchor="0.02495 0.01158 -0.13271" solref="0.001 0.8" solimp="0.99 0.999 0.0001"/> -->
      <!-- <connect name="c2" body1="left_end_link1" body2="end_platform" anchor="0.02495 -0.01158 -0.13271" solref="0.001 0.8" solimp="0.99 0.999 0.0001"/> -->
      <!-- <weld name="c1" body1="right_end_link1" body2="end_platform" solref="0.01 0.9" solimp="0.8 0.9 0.01" torquescale="0.5" />
      <weld name="c2" body1="left_end_link1" body2="end_platform" solref="0.01 0.9" solimp="0.8 0.9 0.01" torquescale="0.5" /> -->
  </equality>  

  <actuator>
    <!-- <motor name="rotor0" ctrllimited="true" ctrlrange="0.0 1.0" gear="0  0 6.5 0. 0. -1" site="motor1"/>
    <motor name="rotor1" ctrllimited="true" ctrlrange="0.0 1.0" gear="0  0 6.5 0. 0.  1" site="motor2"/>
    <motor name="rotor2" ctrllimited="true" ctrlrange="0.0 1.0" gear="0  0 6.5 0. 0. -1" site="motor3"/>
    <motor name="rotor3" ctrllimited="true" ctrlrange="0.0 1.0" gear="0  0 6.5 0. 0.  1" site="motor4"/> -->

    <motor name="forcex" gear="1 0 0 0 0 0" site="UAV_center"/> 
    <motor name="forcey" gear="0 1 0 0 0 0" site="UAV_center"/> 
    <motor name="forcez" gear="0 0 1 0 0 0" site="UAV_center"/> 
    <motor name="Mx" gear="0 0 0 1 0 0" site="UAV_center"/> 
    <motor name="My" gear="0 0 0 0 1 0" site="UAV_center"/> 
    <motor name="Mz" gear="0 0 0 0 0 1" site="UAV_center"/> 

    <motor name="rotor0" gear="0 0 1 0. 0. -1" site="motor1"/>
    <motor name="rotor1" gear="0 0 1 0. 0.  1" site="motor2"/>
    <motor name="rotor2" gear="0 0 1 0. 0. -1" site="motor3"/>
    <motor name="rotor3" gear="0 0 1 0. 0.  1" site="motor4"/>    
      
    <position name="armmotor1" joint="motor_arm_joint1" kp="100" kv="10" />
    <position name="armmotor2" joint="motor_arm_joint2" kp="100" kv="10" />
    <position name="armmotor3" joint="motor_arm_joint3" kp="100" kv="10" />
    <!-- ctrllimited="true" ctrlrange="-1.8 1" -->
    <!-- <velocity name="motor1_vel" joint="motor_arm_joint1" kv="35"/>
    <velocity name="motor2_vel" joint="motor_arm_joint2" kv="35"/>
    <velocity name="motor3_vel" joint="motor_arm_joint3" kv="35"/> -->


  </actuator>  
  
  <sensor>
    <gyro name="body_gyro" site="imu"/>
    <accelerometer name="body_linacc" site="imu"/>
    <framequat name="body_quat" objtype="site" objname="imu"/>  

    <framepos name="ee_pos" objtype="site" objname="end_platform_center" reftype="site" refname="Delta_base_center"/>
    <framelinvel name="ee_lin_vel" objtype="site" objname="end_platform_center" reftype="site" refname="Delta_base_center"/>

    <!-- 末端平台位置传感器 -->
    <!-- <framepos name="ee_pos" objtype="body" objname="end_platform"/>
    <framequat name="ee_quat" objtype="body" objname="end_platform"/>
    <framelinvel name="ee_lin_vel" objtype="body" objname="end_platform"/>
    <frameangvel name="ee_ang_vel" objtype="body" objname="end_platform"/> -->
  </sensor>  

  <visual>
    <global offwidth="1920" offheight="1680"/>
  </visual>

</mujoco>
